Workbook

Sheet commodity_summary
B1: Commodity Code | C1: Description | D1: Average RPC | E1: Average RSC
A2: 1 | B2: 3001 | C2: 111 - Crop Production | D2: 0.4828 | E2: 0.3371
A3: 2 | B3: 3002 | C3: 112 - Animal Production and Aquaculture | D3: 0.7721 | E3: 0.8002
A4: 3 | B4: 3003 | C4: 113 - Forestry and Logging | D4: 0.7772 | E4: 0.512
A5: 4 | B5: 3004 | C5: 114 - Fishing, Hunting and Trapping | D5: 0.3657 | E5: 0.7408
A6: 5 | B6: 3005 | C6: 115 - Support Activities for Agriculture and Forestry | D6: 0.982 | E6: 0.4846
A7: 6 | B7: 3006 | C7: 211 - Oil and Gas Extraction | D7: 0.1288 | E7: 0.6825
A8: 7 | B8: 3007 | C8: 212 - Mining (except Oil and Gas) | D8: 0.3134 | E8: 0.7955
A9: 8 | B9: 3008 | C9: 213 - Support Activities for Mining | D9: 0.198 | E9: 0.9976
A10: 9 | B10: 3009 | C10: 221 - Utilities | D10: 0.6417 | E10: 0.4689
A11: 10 | B11: 3010 | C11: 23 - Construction | D11: 0.9573 | E11: 1
A12: 11 | B12: 3011 | C12: 311 - Food Manufacturing | D12: 0.4278 | E12: 0.5936
A13: 12 | B13: 3012 | C13: 312 - Beverage and Tobacco Product Manufacturing | D13: 0.5673 | E13: 0.5225
... A88: 87 | B88: 3087 | C88: Fruit farming | D88: 0.5339 | E88: 0.2421

Sheet industry_detail
B1: Industry Code | C1: Description | D1: Total Output | E1: Wage and Salary Employment | F1: Employee Compensation | G1: Proprietor Employment | H1: Proprietor Income | I1: Other Property Income | J1: Taxes on Production and Imports Net of Subsidies
A2: 1 | B2: 1 | C2: 111 - Crop Production | D2: 1.9263875e+10 | E2: 70042.83 | F2: 4.3609373e+09 | G2: 39386.72 | H2: 2.9593404e+09 | I2: 5.8312208e+09 | J2: 2.6958594e+08
A3: 2 | B3: 2 | C3: 112 - Animal Production and Aquaculture | D3: 1.795651e+10 | E3: 28405.04 | F3: 9.2640051e+08 | G3: 13021.31 | H3: 7.4732466e+08 | I3: 3.0777779e+09 | J3: 77448874
A4: 3 | B4: 3 | C4: 113 - Forestry and Logging | D4: 8.0663856e+08 | E4: 3541.33 | F4: 3.955565e+08 | G4: 1827.32 | H4: 2.3682529e+08 | I4: 69348345 | J4: 21601407
A5: 4 | B5: 4 | C5: 114 - Fishing, Hunting and Trapping | D5: 3.1710805e+08 | E5: 545.58 | F5: 56623220 | G5: 4446.35 | H5: 1.0503178e+08 | I5: 89377942 | J5: 63411011
A6: 5 | B6: 5 | C6: 115 - Support Activities for Agriculture and Forestry | D6: 1.4764521e+10 | E6: 245075.66 | F6: 1.339349e+10 | G6: 16010.01 | H6: 7.6907345e+08 | I6: -2779702.5 | J6: 5.8760081e+08
A7: 6 | B7: 6 | C7: 211 - Oil and Gas Extraction | D7: 1.1974433e+10 | E7: 3109.11 | F7: 1.0418136e+09 | G7: 14667.41 | H7: 4.4207668e+08 | I7: 2.2692799e+09 | J7: 1.2953619e+09
A8: 7 | B8: 7 | C8: 212 - Mining (except Oil and Gas) | D8: 3.8725935e+09 | E8: 5353.68 | F8: 7.0688064e+08 | G8: 2049.11 | H8: 3.1323058e+08 | I8: 1.3166371e+09 | J8: 1.9881881e+08
A9: 8 | B9: 8 | C9: 213 - Support Activities for Mining | D9: 2.623339e+09 | E9: 6935.36 | F9: 9.5804271e+08 | G9: 2278.7 | H9: 46877348 | I9: 5.7899493e+08 | J9: 1.4860121e+08
A10: 9 | B10: 9 | C10: 221 - Utilities | D10: 9.3106158e+10 | E10: 67084.79 | F10: 1.483185e+10 | G10: 5880.5 | H10: 3.1726348e+09 | I10: 3.5360048e+10 | J10: 1.1040996e+10
A11: 10 | B11: 10 | C11: 23 - Construction | D11: 2.9417517e+11 | E11: 977750.63 | F11: 1.0478454e+11 | G11: 339251.1 | H11: 2.2005385e+10 | I11: 3.9603697e+10 | J11: 3.4029085e+09
A12: 11 | B12: 11 | C12: 311 - Food Manufacturing | D12: 1.1397705e+11 | E12: 184786.51 | F12: 1.4236526e+10 | G12: 12933.01 | H12: 9.3061289e+08 | I12: 8.0198927e+09 | J12: 1.6296063e+09
A13: 12 | B13: 12 | C13: 312 - Beverage and Tobacco Product Manufacturing | D13: 3.2007511e+10 | E13: 65507.21 | F13: 5.9928529e+09 | G13: 4041.9 | H13: 2.0207804e+08 | I13: 3.9831619e+09 | J13: 1.9762802e+09
... A88: 87 | B88: 87 | C88: Fruit farming | D88: 1.7230428e+10 | E88: 78514.04 | F88: 2.2131513e+09 | G88: 17791.61 | H88: 3.0745376e+09 | I88: 4.2515472e+09 | J88: 3.0992703e+08
J89: 2.4611213e+11

Sheet Detail IxI SAM
A1: PayingCode | B1: PayingDescription | C1: ReceivingCode | D1: ReceivingDescription | E1: TransferCode | F1: TransferDescription | G1: Value
A2: 1 | B2: 111 - Crop Production | C2: 1 | D2: 111 - Crop Production | E2: 15055 | F2: Industry Use | G2: 3.5000368e+08
A3: 1 | B3: 111 - Crop Production | C3: 2 | D3: 112 - Animal Production and Aquaculture | E3: 15055 | F3: Industry Use | G3: 20004131
A4: 1 | B4: 111 - Crop Production | C4: 3 | D4: 113 - Forestry and Logging | E4: 15055 | F4: Industry Use | G4: 26271.042
A5: 1 | B5: 111 - Crop Production | C5: 5 | D5: 115 - Support Activities for Agriculture and Forestry | E5: 15055 | F5: Industry Use | G5: 1.0714269e+09
A6: 1 | B6: 111 - Crop Production | C6: 6 | D6: 211 - Oil and Gas Extraction | E6: 15055 | F6: Industry Use | G6: 4173471.3
A7: 1 | B7: 111 - Crop Production | C7: 7 | D7: 212 - Mining (except Oil and Gas) | E7: 15055 | F7: Industry Use | G7: 9474926.3
A8: 1 | B8: 111 - Crop Production | C8: 8 | D8: 213 - Support Activities for Mining | E8: 15055 | F8: Industry Use | G8: 3959.0695
A9: 1 | B9: 111 - Crop Production | C9: 9 | D9: 221 - Utilities | E9: 15055 | F9: Industry Use | G9: 1.4283748e+08
A10: 1 | B10: 111 - Crop Production | C10: 10 | D10: 23 - Construction | E10: 15055 | F10: Industry Use | G10: 46657718
A11: 1 | B11: 111 - Crop Production | C11: 11 | D11: 311 - Food Manufacturing | E11: 15055 | F11: Industry Use | G11: 261125.35
A12: 1 | B12: 111 - Crop Production | C12: 12 | D12: 312 - Beverage and Tobacco Product Manufacturing | E12: 15055 | F12: Industry Use | G12: 427.63126
A13: 1 | B13: 111 - Crop Production | C13: 13 | D13: 313 - Textile Mills | E13: 15055 | F13: Industry Use | G13: 113709.52
... A10009: 28001 | B10009: Domestic Trade | C10009: 14002 | D10009: Inventory Additions/Deletions | E10009: 15051 | F10009: Commodity Trade | G10009: 1.0192615e+09

Sheet IxI pivot
A3: Sum of Value | B3: Column Labels
A4: Row Labels | B4: 1 | C4: 2 | D4: 3 | E4: 4 | F4: 5 | G4: 6 | H4: 7 | I4: 8 | J4: 9 | K4: 10 | L4: 11 | M4: 12 | N4: 13 | O4: 14 | P4: 15 | Q4: 16 | R4: 17 | S4: 18 | T4: 19 | U4: 20 | V4: 21 | W4: 22 | X4: 23 | Y4: 24 | Z4: 25 | AA4: 26 | AB4: 27 | AC4: 28 | AD4: 29 | AE4: 30 | AF4: 31 | AG4: 32 | AH4: 33 | AI4: 34 | AJ4: 35 | AK4: 36 | AL4: 37 | AM4: 38 | AN4: 39 | AO4: 40 | AP4: 41 | AQ4: 42 | AR4: 43 | AS4: 44 | AT4: 45 | AU4: 46 | AV4: 47 | AW4: 48 | AX4: 49 | AY4: 50 | AZ4: 51 | BA4: 52 | BB4: 53 | BC4: 54 | BD4: 55 | BE4: 56 | BF4: 57 | BG4: 58 | BH4: 59 | BI4: 60 | BJ4: 61 | BK4: 62 | BL4: 63 | BM4: 64 | BN4: 65 | BO4: 66 | BP4: 67 | BQ4: 68 | BR4: 69 | BS4: 70 | BT4: 71 | BU4: 72 | BV4: 73 | BW4: 74 | BX4: 75 | BY4: 76 | BZ4: 77 | CA4: 78 | CB4: 79 | CC4: 80 | CD4: 81 | CE4: 82 | CF4: 83 | CG4: 85 | CH4: 86 | CI4: 87 | CJ4: 5001 | CK4: 6001 | CL4: 7001 | CM4: 8001 | CN4: 10001 | CO4: 10002 | CP4: 10003 | CQ4: 10004 | CR4: 10005 | CS4: 10006 | CT4: 10007 | CU4: 10008 | CV4: 10009 | CW4: 11001 | CX4: 11002 | CY4: 11003 | CZ4: 12001 | DA4: 12002 | DB4: 12003 | DC4: 12004 | DD4: 13001 | DE4: 14001 | DF4: 14002 | DG4: 25001 | DH4: 28001 | DI4: Grand Total
A5: 1 | B5: 3.5000368e+08 | C5: 3.3876685e+08 | D5: 6476600.7 | E5: 177.57912 | F5: 119434.91 | H5: 388693.05 | I5: 89626.476 | J5: 5018.2717 | K5: 77333386 | L5: 3.1613548e+09 | M5: 88518566 | N5: 8898969.3 | O5: 307.24735 | P5: 8624970.8 | Q5: 147370.67 | R5: 67456209 | S5: 2572527 | T5: 169451.31 | U5: 740.96881 | V5: 2.8777525e+08 | W5: 9412174.4 | X5: 39748.938 | Y5: 4018.08 | Z5: 3238.0838 | AA5: 3920.8077 | AB5: 41106.795 | AC5: 4074.6214 | AD5: 16024.14 | AE5: 721216.84 | AF5: 14726032 | AG5: 2276261.9 | AH5: 12539322 | AI5: 1711.7622 | AJ5: 2715.3615 | AK5: 7745341.4 | AL5: 2875.9914 | AM5: 4764014.2 | AN5: 3176.8186 | AO5: 15981.199 | AP5: 543367.16 | AR5: 13294.19 | AT5: 4668.8731 | AV5: 29.10344 | AW5: 24807.807 | AX5: 140.96415 | AY5: 2429.0103 | AZ5: 3389.2414 | BA5: 4593.5178 | BB5: 3541.7297 | BC5: 13101.164 | BD5: 48360.45 | BE5: 14600.84 | BF5: 12127.848 | BG5: 31166.779 | BH5: 49524.649 | BI5: 2904.097 | BJ5: 3422.3683 | BK5: 540085.91 | BL5: 20402.651 | BN5: 27273529 | BO5: 341187.06 | BP5: 92326280 | BQ5: 4089.2611 | BR5: 1940220.3 | BS5: 39002.765 | BT5: 4749.1152 | BU5: 3462.7923 | BV5: 24264.339 | BW5: 31906.65 | BY5: 2756045.3 | BZ5: 430027.85 | CA5: 2869076.2 | CB5: 3836.6812 | CC5: 2983.8288 | CD5: 607244.8 | CF5: 40110.761 | CH5: 17115400 | CI5: 14958024 | CN5: 55011829 | CO5: 62071826 | CP5: 51558299 | CQ5: 60737985 | CR5: 1.5131388e+08 | CS5: 2.028119e+08 | CT5: 3.495471e+08 | CU5: 2.7335106e+08 | CV5: 5.8357399e+08 | CW5: 4969562.8 | CX5: 1635.6765 | CY5: 82.413125 | CZ5: 1.6760034e+08 | DA5: 8089421.3 | DB5: 2377363.6 | DE5: 252771.23 | DF5: 6587933.5 | DG5: 6.3422223e+09 | DH5: 6.3286632e+09 | DI5: 1.9263875e+10
A6: 2 | B6: 20004131 | C6: 2.2761685e+09 | D6: 280654.08 | E6: 194.50563 | F6: 832586.67 | H6: 1.1188251 | I6: 185.11211 | J6: 5588.7798 | K6: 17730.175 | L6: 9.551859e+09 | M6: 309073.33 | N6: 1713479 | O6: 5075172.9 | P6: 73504.49 | Q6: 1255.9354 | R6: 572851.41 | S6: 22768.848 | T6: 2438.5706 | U6: 825.20671 | V6: 37515.769 | W6: 81566.014 | X6: 2138.1401 | Y6: 410.55086 | Z6: 2558.1698 | AA6: 679.98761 | AB6: 655.11861 | AD6: 788.40956 | AE6: 6113.9405 | AF6: 1247973.5 | AG6: 88381.355 | AH6: 700.08895 | AI6: 1659.9098 | AJ6: 2569.8864 | AK6: 4660.1209 | AL6: 43.987443 | AM6: 3917.8432 | AN6: 62.280961 | AO6: 15684.617 | AP6: 102003.95 | AW6: 362728.33 | AY6: 157.13938 | AZ6: 3400.3708 | BA6: 2955.1556 | BB6: 297.38853 | BC6: 5601.4112 | BD6: 30357.854 | BE6: 9846.3995 | BF6: 13102.268 | BG6: 34620.456 | BH6: 21624.741 | BI6: 3234.2526 | BJ6: 3811.4442 | BK6: 146.6861 | BL6: 12274.585 | BN6: 1.7148299e+08 | BO6: 2023212.5 | BP6: 1070195.1 | BQ6: 4276.8112 | BR6: 6709281.6 | BS6: 36249.125 | BT6: 1325.687 | BU6: 3814.0673 | BV6: 13658.92 | BW6: 35411.105 | BY6: 36490752 | BZ6: 2358002.9 | CA6: 3.1742412e+08 | CB6: 1680.5171 | CC6: 3002.8924 | CD6: 178132.95 | CF6: 34057.747 | CH6: 23836904 | CI6: 53965282 | CN6: 72814811 | CO6: 73927106 | CP6: 59091510 | CQ6: 66499060 | CR6: 1.5981715e+08 | CS6: 1.9798674e+08 | CT6: 3.1023926e+08 | CU6: 2.4604752e+08 | CV6: 4.8388357e+08 | CW6: 131.95518 | CX6: 2140964.2 | CZ6: 99671832 | DA6: 2954875.4 | DB6: 38809810 | DF6: 57306791 | DG6: 45033692 | DH6: 3.5655686e+09 | DI6: 1.795651e+10
A7: 3 | B7: 26271.042 | C7: 25724.501 | D7: 18717017 | F7: 6178.0757 | H7: 421.35742 | I7: 6.8234766 | K7: 5849.4683 | L7: 78494312 | M7: 14372046 | N7: 680.95768 | P7: 25732145 | Q7: 439672.61 | R7: 2.0032159e+08 | S7: 7649702.5 | T7: 502738.93 | V7: 12986809 | W7: 28046349 | X7: 101741.61 | AE7: 1896971.7 | AF7: 12507925 | AG7: 163.18034 | AH7: 959.32346 | AK7: 591.30149 | AM7: 364.23302 | AP7: 41.405001 | AW7: 1.8684839 | BH7: 2.2649789 | BK7: 28.635415 | BN7: 4284158.4 | BO7: 16.253479 | BP7: 301460.37 | BR7: 345652.34 | BY7: 206.54916 | BZ7: 28.940259 | CA7: 208.20818 | CD7: 45.365127 | CH7: 435.11688 | CN7: 4072.2602 | CO7: 4560.4275 | CP7: 3774.9107 | CQ7: 4500.5543 | CR7: 11307.096 | CS7: 15129.226 | CT7: 25903.501 | CU7: 20151.828 | CV7: 43258.42 | CW7: 380.22431 | CZ7: 12202.281 | DA7: 614.93822 | DB7: 181.56374 | DF7: 5845719.3 | DG7: 81326849 | DH7: 3.1255143e+08 | DI7: 8.0663856e+08
A8: 4 | L8: 44900790 | V8: 69107.703 | AK8: 4618407.2 | AW8: 2999.5721 | BN8: 401153.58 | BR8: 584992.13 | BY8: 2253892.2 | BZ8: 3517546.3 | CA8: 63700216 | CD8: 1333627.6 | CF8: 1312.8851 | CN8: 7051647 | CO8: 5413076.1 | CP8: 3636610.1 | CQ8: 6670115.3 | CR8: 6224911.4 | CS8: 13966019 | CT8: 21297172 | CU8: 11960842 | CV8: 27860890 | CZ8: 3353589.7 | DA8: 463624.1 | DB8: 5535505.4 | DF8: 94697.441 | DG8: 79598687 | DH8: 2596621.2 | DI8: 3.1710805e+08
A9: 5 | B9: 1.0714269e+09 | C9: 4.1503957e+08 | D9: 32537106 | E9: 27856.389 | BN9: 97216934 | BO9: 3227933.2 | CH9: 1.8278219e+09 | CI9: 2.3946997e+09 | CN9: 1933651.5 | CO9: 2132879.7 | CP9: 1945303.5 | CQ9: 1986615.9 | CR9: 5350634 | CS9: 4735380.8 | CT9: 6753597.8 | CU9: 6411981.5 | CV9: 12130747 | CZ9: 1.268897e+09 | DG9: 36054973 | DH9: 7.5741902e+09 | DI9: 1.4764521e+10
A10: 6 | B10: 4173471.3 | C10: 3992392.6 | D10: 2679.2508 | E10: 3947.16 | F10: 2106.7942 | G10: 1.1734962e+08 | H10: 1086431.2 | I10: 454602.43 | J10: 4.9639964e+08 | K10: 95129386 | L10: 3677437.2 | M10: 880453.02 | N10: 64010.425 | O10: 32608.021 | P10: 153.20238 | Q10: 6737.2681 | R10: 1111648.7 | S10: 1217828.1 | T10: 675249.88 | U10: 6.3241975e+09 | V10: 26551719 | W10: 993644.59 | X10: 1279687.4 | Y10: 887570.29 | Z10: 1702004.1 | AA10: 1036274.6 | AB10: 2320499.2 | AC10: 1521050.5 | AD10: 867972.7 | AE10: 394673.17 | AF10: 1941835.3 | AG10: 8608050.2 | AH10: 878486.72 | AI10: 30152.575 | AJ10: 308016.02 | AK10: 624983.79 | AL10: 91788.658 | AM10: 207143.1 | AN10: 180610.51 | AO10: 277254.27 | AP10: 300796.33 | AQ10: 41965872 | AR10: 3907900.1 | AS10: 5099197.7 | AT10: 37430550 | AU10: 8081658.5 | AV10: 274518.45 | AW10: 824425.28 | AX10: 3132621.1 | AY10: 7902867.2 | AZ10: 250131.29 | BA10: 268527.03 | BB10: 96285.86 | BC10: 693525.19 | BD10: 1382398.6 | BE10: 828582.44 | BF10: 3093071.6 | BG10: 7259110.9 | BH10: 3059569.7 | BI10: 41443.823 | BJ10: 1333657.5 | BK10: 15023625 | BL10: 3361524.8 | BM10: 770187.84 | BN10: 7023835.7 | BO10: 1385774.9 | BP10: 9579894 | BQ10: 3170632.5 | BR10: 7916522 | BS10: 1712190.7 | BT10: 1917450.9 | BU10: 1280094.5 | BV10: 1585246.9 | BW10: 494327.32 | BX10: 87378.599 | BY10: 2009157.3 | BZ10: 1584805 | CA10: 8264881.8 | CB10: 2400186.4 | CC10: 1211546.7 | CD10: 2530051.2 | CF10: 4.0166575e+08 | CH10: 2946357.4 | CI10: 1792671.5 | CN10: 10406658 | CO10: 12921015 | CP10: 11759338 | CQ10: 13101844 | CR10: 33554073 | CS10: 42534635 | CT10: 68828495 | CU10: 47798846 | CV10: 91764559 | CW10: 973700.29 | CX10: 38760719 | CY10: 706.8717 | CZ10: 1.6800776e+08 | DA10: 54161177 | DB10: 12648041 | DC10: 8886.1661 | DE10: 2950874.4 | DF10: 8036498.2 | DG10: 3.5387288e+09 | DH10: 1.0938401e+08 | DI10: 1.1974433e+10
A11: 7 | B11: 9474926.3 | C11: 7329170.8 | D11: 14.339965 | E11: 51.079472 | F11: 5147.4062 | G11: 1650095.8 | H11: 73517378 | I11: 407615.43 | J11: 4.2419714e+08 | K11: 6.4168298e+08 | L11: 46566718 | M11: 7635269.1 | N11: 1524454.2 | O11: 542278.08 | P11: 5511.2412 | Q11: 13090.29 | R11: 575234.69 | S11: 12143291 | T11: 519176.67 | U11: 92341707 | V11: 1.6892475e+08 | W11: 8402869.8 | X11: 3.3882914e+08 | Y11: 1.5165705e+08 | Z11: 19911855 | AA11: 3640828.6 | AB11: 3881332.4 | AC11: 3288312.4 | AD11: 6066007.6 | AE11: 601637.04 | AF11: 6328362.7 | AG11: 1744137.9 | AH11: 21326.031 | AI11: 2534.9646 | AJ11: 3611.2322 | AK11: 11315.647 | AL11: 5744.4173 | AM11: 3044.1958 | AN11: 89210.798 | AO11: 23750.903 | AP11: 4149.7976 | AQ11: 224704.79 | AR11: 1718616.2 | AS11: 27881.044 | AT11: 460999.48 | AU11: 137584.05 | AV11: 985.22414 | AW11: 30205.093 | AX11: 17709.357 | AY11: 160340.23 | AZ11: 364096.77 | BA11: 1746912.4 | BB11: 6520385.5 | BC11: 4112023.5 | BD11: 2304796.4 | BE11: 55596390 | BF11: 18983.009 | BG11: 48209.966 | BH11: 20342.839 | BI11: 3163.0036 | BJ11: 7138.0407 | BK11: 2300278.5 | BL11: 98644.168 | BM11: 13698.753 | BN11: 68273966 | BO11: 1565871 | BP11: 38510155 | BQ11: 3449983.3 | BR11: 28049653 | BS11: 3544068 | BT11: 5161848.4 | BU11: 1502522.6 | BV11: 1343949.7 | BW11: 14228143 | BX11: 76538.767 | BY11: 30922493 | BZ11: 5423069.2 | CA11: 42203720 | CB11: 8646329.1 | CC11: 38043453 | CD11: 10145497 | CF11: 2.2620616e+08 | CH11: 7449937.5 | CI11: 3573634.5 | CN11: 1172916.5 | CO11: 2095126.3 | CP11: 1623258.6 | CQ11: 1918456.8 | CR11: 5134694.3 | CS11: 4886285.9 | CT11: 7586122.3 | CU11: 5448868.2 | CV11: 10902208 | CW11: 41934868 | CX11: 1553355.9 | CZ11: 98187380 | DA11: 11536933 | DB11: 37856241 | DE11: 45728851 | DF11: 763619.76 | DG11: 3.0248288e+08 | DH11: 6.4395417e+08 | DI11: 3.8725935e+09
A12: 8 | B12: 3959.0695 | C12: 13529.36 | D12: 1.675336 | E12: 12.517858 | F12: 3.171165 | G12: 13164549 | H12: 545444.29 | I12: 725832.3 | J12: 20392.903 | K12: 1333632 | L12: 140842.32 | M12: 100865.18 | N12: 1431.7779 | O12: 1770.5807 | P12: 368.91522 | Q12: 263.05178 | R12: 24880.823 | S12: 30373.594 | T12: 7272.4445 | U12: 29302.741 | V12: 78968.955 | W12: 48947.132 | X12: 19298.536 | Y12: 22232.738 | Z12: 364025.89 | AA12: 178233.3 | AB12: 475936.74 | AC12: 125128.52 | AD12: 317739.76 | AE12: 38292.422 | AF12: 75599.448 | AG12: 33080.843 | AH12: 2554.2504 | AI12: 441.60212 | AJ12: 372.68977 | AK12: 1527.4506 | AL12: 584.49818 | AM12: 580.45027 | AN12: 870.7237 | AO12: 4296.3859 | AP12: 834.73487 | AQ12: 28734.847 | AR12: 4597.1657 | AS12: 23567.723 | AT12: 44958.134 | AU12: 13703.428 | AV12: 26270.727 | AW12: 1344.6081 | AX12: 2529.7969 | AY12: 11172.152 | AZ12: 9199.0878 | BA12: 707.65986 | BB12: 40615.584 | BC12: 51165.779 | BD12: 20611.203 | BE12: 11843.998 | BF12: 2904.4227 | BG12: 6624.096 | BH12: 2716.4885 | BI12: 25.704051 | BJ12: 1112.2656 | BK12: 36702.722 | BL12: 23620.23 | BM12: 481.59859 | BN12: 226095.85 | BO12: 10420.668 | BP12: 34368.506 | BQ12: 41367.696 | BR12: 9582.5012 | BS12: 5883.4643 | BT12: 11133.869 | BU12: 1023.0809 | BV12: 28977.046 | BW12: 990.17243 | BX12: 71.288276 | BY12: 6224.644 | BZ12: 13829.528 | CA12: 46778.283 | CB12: 74239.461 | CC12: 3631.2883 | CD12: 12379.3 | CF12: 191278.24 | CH12: 3855.5697 | CI12: 2302.4113 | CN12: 12742.533 | CO12: 17100.902 | CP12: 14758.709 | CQ12: 16370.687 | CR12: 46653.842 | CS12: 56951.927 | CT12: 87470.318 | CU12: 66331.879 | CV12: 150903.15 | CW12: 4290.6708 | CX12: 170422.64 | CY12: 3539.2473 | CZ12: 192407.19 | DA12: 38073.062 | DB12: 21664.489 | DC12: 1757.1463 | DE12: 2.5938345e+09 | DF12: 37061.429 | DG12: 5830053 | DH12: 3711990.5 | DI12: 2.623339e+09
A13: 9 | B13: 1.4283748e+08 | C13: 1.0755043e+08 | D13: 23327.794 | E13: 13537.649 | F13: 92923.83 | G13: 1.0399539e+08 | H13: 40465758 | I13: 4084343.6 | J13: 4.4203523e+09 | K13: 5.5767854e+08 | L13: 3.9651955e+08 | M13: 79381037 | N13: 14151332 | O13: 6359190.8 | P13: 1027474.2 | Q13: 910010.85 | R13: 66275230 | S13: 1.0042095e+08 | T13: 52174993 | U13: 4.5453456e+08 | V13: 6.5114819e+08 | W13: 1.7636253e+08 | X13: 2.1976898e+08 | Y13: 1.0477778e+08 | Z13: 2.3444034e+08 | AA13: 79814024 | AB13: 9.287127e+08 | AC13: 71595599 | AD13: 2.4047652e+08 | AE13: 29963409 | AF13: 82007185 | AG13: 8.7304869e+08 | AH13: 1.2284053e+08 | AI13: 8875751.3 | AJ13: 32174351 | AK13: 3.213472e+08 | AL13: 62776905 | AM13: 90652003 | AN13: 83837751 | AO13: 82873666 | AP13: 2.3777379e+08 | AQ13: 14431954 | AR13: 2051014.5 | AS13: 15620286 | AT13: 2.6022516e+08 | AU13: 36245665 | AV13: 42612105 | AW13: 21525795 | AX13: 5597721.4 | AY13: 1.2901885e+08 | AZ13: 36666023 | BA13: 61966723 | BB13: 32353697 | BC13: 1.0061746e+08 | BD13: 1.9811272e+08 | BE13: 1.5473887e+08 | BF13: 20708752 | BG13: 84196153 | BH13: 1.1178399e+08 | BI13: 29463542 | BJ13: 1.5090145e+08 | BK13: 3.1182426e+09 | BL13: 99219174 | BM13: 34679836 | BN13: 4.795557e+08 | BO13: 2.129807e+08 | BP13: 1.6872126e+08 | BQ13: 1.0019787e+08 | BR13: 3.2324623e+08 | BS13: 3.6106567e+08 | BT13: 3.3386568e+08 | BU13: 1.9133307e+08 | BV13: 91717044 | BW13: 69914978 | BX13: 13666927 | BY13: 1.8243285e+08 | BZ13: 3.5453467e+08 | CA13: 1.4243752e+09 | CB13: 1.795332e+08 | CC13: 1.5469271e+08 | CD13: 1.0966294e+08 | CF13: 2.65235e+09 | CH13: 2.6341445e+08 | CI13: 2.5045239e+08 | CN13: 6.9080499e+08 | CO13: 8.9427861e+08 | CP13: 7.396153e+08 | CQ13: 7.7582238e+08 | CR13: 1.7233254e+09 | CS13: 2.0577241e+09 | CT13: 3.1371771e+09 | CU13: 2.2148899e+09 | CV13: 4.487042e+09 | CW13: 29960511 | CX13: 4.6652907e+08 | CZ13: 1.6784246e+09 | DA13: 4.7132635e+08 | DB13: 5.8407238e+08 | DG13: 3.1988444e+08 | DH13: 4.8872472e+10 | DI13: 9.3106158e+10
A14: 10 | B14: 46657718 | C14: 19524971 | E14: 12576.927 | F14: 53787.845 | G14: 9992563.1 | H14: 63769688 | I14: 29847410 | J14: 3.8170645e+08 | K14: 37463381 | L14: 1.9070259e+08 | M14: 38437345 | N14: 4052221.1 | O14: 2002102.3 | P14: 500502.69 | Q14: 436143.33 | R14: 30503274 | S14: 57639372 | T14: 24705458 | U14: 1.6085577e+09 | V14: 1.5754694e+08 | W14: 59262257 | X14: 1.0304464e+08 | Y14: 47865176 | Z14: 1.4188555e+08 | AA14: 61786815 | AB14: 4.7232363e+08 | AC14: 27171754 | AD14: 1.1412144e+08 | AE14: 12871511 | AF14: 60800315 | AG14: 4.2094259e+08 | AH14: 77857800 | AI14: 3533566.7 | AJ14: 17701652 | AK14: 75608919 | AL14: 21128489 | AM14: 62398819 | AN14: 42669369 | AO14: 33434819 | AP14: 1.3383148e+08 | AQ14: 27440115 | AR14: 1.3406578e+08 | AS14: 5980123.6 | AT14: 75785791 | AU14: 83831080 | AV14: 64869638 | AW14: 34440285 | AX14: 11440235 | AY14: 86453284 | AZ14: 10158491 | BA14: 30190294 | BB14: 9281085.1 | BC14: 2.1481673e+08 | BD14: 40970773 | BE14: 1.773365e+08 | BF14: 50310272 | BG14: 2.1325605e+08 | BH14: 3.5180599e+08 | BI14: 51797522 | BJ14: 9234151.8 | BK14: 1.8560529e+10 | BL14: 1.0670646e+08 | BN14: 2.8053611e+08 | BO14: 76502467 | BP14: 1.0417844e+08 | BQ14: 17238877 | BR14: 59788886 | BS14: 1.4991754e+08 | BT14: 1.0037653e+08 | BU14: 67427680 | BV14: 67729565 | BW14: 17156043 | BX14: 6547900.5 | BY14: 78765835 | BZ14: 5.5888071e+08 | CA14: 3.0711319e+08 | CB14: 95095474 | CC14: 77050477 | CD14: 3.073224e+08 | CF14: 1.3389139e+10 | CH14: 97896335 | CI14: 71954937 | CW14: 29149269 | CX14: 2.8062932e+09 | CY14: 3.4121717e+09 | CZ14: 8.5991377e+09 | DA14: 1.7794371e+09 | DB14: 2.0930176e+09 | DC14: 4.7332005e+10 | DE14: 1.871351e+11 | DG14: 13122292 | DH14: 61539.992 | DI14: 2.9417517e+11
A15: 11 | B15: 261125.35 | C15: 1.5603034e+09 | D15: 3.078126 | E15: 21033.827 | F15: 389916.21 | G15: 119725.92 | H15: 23998.258 | I15: 13024.694 | J15: 50556.012 | K15: 697161.86 | L15: 1.1766211e+10 | M15: 8.4238998e+08 | N15: 89305.701 | O15: 2026333.6 | P15: 30741.136 | Q15: 7640039.1 | R15: 2424727.8 | S15: 3226552.7 | T15: 21571574 | U15: 23485603 | V15: 3.0511913e+08 | W15: 22416838 | X15: 74467046 | Y15: 158164.64 | Z15: 297371.31 | AA15: 56761.082 | AB15: 571922.95 | AC15: 121209.56 | AD15: 486963.71 | AE15: 60319.889 | AF15: 741535.29 | AG15: 1.847361e+08 | AH15: 6572.5314 | AI15: 661.82997 | AJ15: 1202.2315 | AK15: 40193708 | AL15: 2570.7569 | AM15: 24968.246 | AN15: 7988.486 | AO15: 6225.3367 | AP15: 9451330.9 | AQ15: 10339915 | AR15: 61846.272 | AS15: 14689082 | AT15: 1117987.4 | AU15: 11549.662 | AV15: 303.90063 | AW15: 138633.72 | AX15: 3738.0179 | AY15: 18266.36 | AZ15: 1000014 | BA15: 3553453.8 | BB15: 2878.8835 | BC15: 19062.015 | BD15: 17824.509 | BE15: 33378995 | BF15: 6908.0105 | BG15: 18734.424 | BH15: 6837.7024 | BI15: 3970.5513 | BJ15: 2044.3619 | BK15: 639829.23 | BL15: 9439.9074 | BM15: 2062.6876 | BN15: 5.6238442e+08 | BO15: 3360964.6 | BP15: 383973.85 | BQ15: 110729.71 | BR15: 3.5086222e+08 | BS15: 1327300.6 | BT15: 2.9072484e+08 | BU15: 3.192618e+08 | BV15: 1.1578441e+09 | BW15: 34257767 | BX15: 918841.8 | BY15: 1.8447241e+08 | BZ15: 2.5340203e+08 | CA15: 5.3427589e+09 | CB15: 113599.02 | CC15: 540345.75 | CD15: 1.1304843e+08 | CF15: 617433.86 | CH15: 456834.59 | CI15: 319246.14 | CN15: 1.7431516e+09 | CO15: 1.6629454e+09 | CP15: 1.3266106e+09 | CQ15: 1.6019981e+09 | CR15: 3.7836708e+09 | CS15: 4.7554149e+09 | CT15: 7.3564301e+09 | CU15: 5.1625572e+09 | CV15: 1.0198615e+10 | CW15: 1731317.4 | CX15: 5.6434554e+08 | CY15: 24701.293 | CZ15: 2.0991004e+09 | DA15: 1.0798174e+09 | DB15: 2.289563e+09 | DC15: 16569.025 | DE15: 450088.17 | DF15: 3.791559e+08 | DG15: 4.8270723e+09 | DH15: 4.1592266e+10 | DI15: 1.1397705e+11
A16: 12 | B16: 427.63126 | C16: 37303338 | D16: 0.0010056252 | E16: 48.138239 | F16: 890.86992 | G16: 185.79834 | H16: 73.263958 | I16: 28.185254 | J16: 82.558412 | K16: 5567.1486 | L16: 1.7391258e+08 | M16: 7.8744555e+08 | N16: 256.88718 | O16: 4611.292 | P16: 13.894698 | Q16: 17406.084 | R16: 6718.2907 | S16: 51467.653 | T16: 59464.51 | U16: 52257.859 | V16: 703284 | W16: 54133.923 | X16: 172934.01 | Y16: 1097.3046 | Z16: 2541.8013 | AA16: 1991.6936 | AB16: 5318.2369 | AC16: 2766.8788 | AD16: 9239.6591 | AE16: 1846.7768 | AF16: 6855.8526 | AG16: 1738701 | AH16: 134.41735 | AI16: 23.096142 | AJ16: 34.801608 | AK16: 92928.779 | AL16: 232.19184 | AM16: 99.577592 | AN16: 321.29574 | AO16: 197.82463 | AP16: 21913.9 | AQ16: 24962216 | AR16: 156.53364 | AS16: 2046705 | AT16: 1086692.2 | AU16: 2762.2464 | AV16: 55.444381 | AW16: 51750.58 | AX16: 262.64467 | AY16: 366.59228 | AZ16: 2876.6763 | BA16: 8304.5233 | BB16: 14.336872 | BC16: 493.48821 | BD16: 243.78202 | BE16: 76759.816 | BF16: 377.94542 | BG16: 718.54537 | BH16: 432.56499 | BI16: 470.03548 | BJ16: 2.9695605 | BK16: 2808.407 | BL16: 331.17919 | BM16: 2569.4487 | BN16: 33418516 | BO16: 1662802.5 | BP16: 5827.3802 | BQ16: 640.918 | BR16: 44410282 | BS16: 6244.628 | BT16: 18851893 | BU16: 8764808.8 | BV16: 15014071 | BW16: 4334010.7 | BX16: 3556207.5 | BY16: 1.8241943e+08 | BZ16: 70927637 | CA16: 1.7332193e+09 | CB16: 618.92084 | CC16: 1388.2525 | CD16: 32247507 | CF16: 75486.495 | CH16: 2067.7036 | CI16: 1704.5255 | CN16: 6.0141295e+08 | CO16: 6.1702848e+08 | CP16: 5.2355485e+08 | CQ16: 5.4052395e+08 | CR16: 1.2737345e+09 | CS16: 1.5116312e+09 | CT16: 2.5930332e+09 | CU16: 1.854697e+09 | CV16: 3.2541527e+09 | CW16: 5206.9466 | CX16: 18151049 | CZ16: 4.4626585e+08 | DA16: 45412274 | DB16: 80965532 | DE16: 408.36103 | DF16: 2.0360364e+08 | DG16: 1.0234949e+09 | DH16: 1.4240998e+10 | DI16: 3.2007511e+10
A17: 13 | B17: 113709.52 | C17: 51915.483 | E17: 52.420503 | F17: 837.7968 | G17: 48280.857 | H17: 9633.6933 | I17: 5282.9214 | J17: 18299.806 | K17: 3237764.1 | L17: 169741.38 | M17: 26401.431 | N17: 55964913 | O17: 32952931 | P17: 85821438 | Q17: 603580.37 | R17: 2794553.4 | S17: 13937351 | T17: 2341861.5 | U17: 846512.39 | V17: 1815072.2 | W17: 5130477.9 | X17: 1366891.4 | Y17: 17858.594 | Z17: 141740.31 | AA17: 5684240.3 | AB17: 303752.52 | AC17: 52611.638 | AD17: 3670469.4 | AE17: 33887970 | AF17: 61809016 | AG17: 10174735 | AH17: 73597.044 | AI17: 391866.9 | AJ17: 679.91642 | AK17: 17385.561 | AL17: 4378.6305 | AM17: 1113.7717 | AN17: 4549001.4 | AO17: 3861033.2 | AP17: 339400.79 | AQ17: 264.49188 | AR17: 1713.9742 | AS17: 13893.835 | AT17: 11074.771 | AU17: 1212.2872 | AV17: 567.45915 | AW17: 3628.7398 | AX17: 2047.6535 | AY17: 5974.9848 | AZ17: 10502.851 | BA17: 6374390.7 | BB17: 4201.9633 | BC17: 15321.077 | BD17: 7086.03 | BE17: 40459.973 | BF17: 427.66919 | BG17: 1733.9523 | BH17: 624.8073 | BI17: 1365.4594 | BJ17: 2.370965 | BK17: 297680.11 | BL17: 361624.8 | BM17: 1835.7235 | BN17: 6306257.6 | BO17: 180414.88 | BP17: 255239.79 | BQ17: 73991.137 | BR17: 500421.19 | BS17: 856988.94 | BT17: 680999.51 | BU17: 255511.47 | BV17: 5159554.7 | BW17: 1947.273 | BX17: 2232.971 | BY17: 1463441 | BZ17: 210290.05 | CA17: 767160.1 | CB17: 1671350.4 | CC17: 530012.87 | CD17: 36574.383 | CF17: 83735.569 | CH17: 218275.77 | CI17: 157394.71 | CN17: 684207.23 | CO17: 968165.58 | CP17: 699827.07 | CQ17: 866457.13 | CR17: 2207640.1 | CS17: 2833121.6 | CT17: 5224471.9 | CU17: 3727129.4 | CV17: 14592938 | CW17: 183886.32 | CX17: 2584710.3 | CY17: 2353.0681 | CZ17: 1568405.3 | DA17: 144205.08 | DB17: 1543314.1 | DC17: 1657.7778 | DE17: 2017479.8 | DF17: 718786.98 | DG17: 1.6914437e+08 | DH17: 1.1013333e+09 | DI17: 1.6698542e+09
A18: 14 | B18: 518399.24 | C18: 151013.48 | D18: 0.039734832 | E18: 3936.1435 | F18: 9330.0193 | G18: 19788.921 | H18: 29404.243 | I18: 13812.983 | J18: 15658.506 | K18: 38395545 | L18: 6341085.8 | M18: 1365980.4 | N18: 175996.84 | O18: 3371106.4 | P18: 2383937.1 | Q18: 12522.48 | R18: 1724741.5 | S18: 220092.35 | T18: 516005.57 | U18: 174549.74 | V18: 1490033.5 | W18: 3061536.6 | X18: 1043172.2 | Y18: 45620.072 | Z18: 498256.97 | AA18: 804199.29 | AB18: 2777360.1 | AC18: 390181.9 | AD18: 57306670 | AE18: 3048982.7 | AF18: 1415818.7 | AG18: 38717712 | AH18: 533580.81 | AI18: 41193.446 | AJ18: 64248.448 | AK18: 1498907.2 | AL18: 360179.92 | AM18: 115878.39 | AN18: 4939289.3 | AO18: 281112.57 | AP18: 26333286 | AQ18: 46700.873 | AR18: 4125.0994 | AS18: 1093973 | AT18: 825304.62 | AU18: 94263.857 | AV18: 41856.685 | AW18: 278566.48 | AX18: 204741.75 | AY18: 182655.24 | AZ18: 249624.82 | BA18: 217659.45 | BB18: 596946.79 | BC18: 464163.54 | BD18: 259154.6 | BE18: 2394330.1 | BF18: 69318.309 | BG18: 294228.52 | BH18: 69466.491 | BI18: 405846.13 | BJ18: 514.83467 | BK18: 3547079 | BL18: 2191919 | BM18: 393747.44 | BN18: 8024947.3 | BO18: 280385.54 | BP18: 2703005.5 | BQ18: 2358438.6 | BR18: 623362.06 | BS18: 1817170.9 | BT18: 3689789.1 | BU18: 18660515 | BV18: 29941490 | BW18: 110224.24 | BX18: 94238.669 | BY18: 5968217.4 | BZ18: 16413887 | CA18: 5196593.2 | CB18: 1637565.6 | CC18: 7115264.2 | CD18: 2352267.6 | CF18: 1816829 | CH18: 2408279.4 | CI18: 2051757.9 | CN18: 5688941.6 | CO18: 7629128.2 | CP18: 9100283.3 | CQ18: 7475904.4 | CR18: 17619212 | CS18: 26740451 | CT18: 51549922 | CU18: 47000650 | CV18: 1.2822067e+08 | CW18: 1546491.9 | CX18: 36024602 | CY18: 302476.57 | CZ18: 17959239 | DA18: 2635604.9 | DB18: 32914158 | DC18: 192175.43 | DE18: 1.2652693e+08 | DF18: 1491015.4 | DG18: 1.2854149e+08 | DH18: 9.708709e+08 | DI18: 1.9474308e+09
A19: 15 | B19: 6789.9335 | C19: 2791.0912 | E19: 36.860195 | F19: 84.802176 | G19: 158.59181 | H19: 739.31041 | I19: 363.25112 | J19: 1218.2462 | K19: 503349.1 | L19: 119692.19 | M19: 31032.877 | N19: 1621519.8 | O19: 1337774.6 | P19: 17197801 | Q19: 16418.362 | R19: 88096.31 | S19: 357555.43 | T19: 20472649 | U19: 3457.4425 | V19: 53208.776 | W19: 175267.31 | X19: 44806.829 | Y19: 716.44813 | Z19: 9796.6497 | AA19: 163051.98 | AB19: 73902.504 | AC19: 9552.478 | AD19: 597185.45 | AE19: 894832.95 | AF19: 1598156.2 | AG19: 8446310.9 | AH19: 23754.807 | AI19: 15303.308 | AJ19: 3998.7744 | AK19: 41514.487 | AL19: 16264.967 | AM19: 8605.9993 | AN19: 670916.57 | AO19: 130184.96 | AP19: 3189405 | AQ19: 1442.9171 | AR19: 232.44901 | AS19: 9512.6598 | AT19: 19333.404 | AU19: 10222.054 | AV19: 661.53747 | AW19: 5592.7602 | AX19: 3754.703 | AY19: 2714.2065 | AZ19: 51248.89 | BA19: 287593.55 | BB19: 189784.59 | BC19: 6459821 | BD19: 23543.623 | BE19: 535035.02 | BF19: 15123.202 | BG19: 63390.047 | BH19: 14907.523 | BI19: 86580.923 | BK19: 40946.201 | BL19: 2866939.9 | BM19: 48274.927 | BN19: 1364585.7 | BO19: 72070.936 | BP19: 1507069.6 | BQ19: 286571.48 | BR19: 918962.08 | BS19: 537243.38 | BT19: 219086.67 | BU19: 175475.95 | BV19: 22407643 | BW19: 1828753.6 | BX19: 21667.194 | BY19: 367393.21 | BZ19: 265578.2 | CA19: 2637144.1 | CB19: 2655349.6 | CC19: 374004.77 | CD19: 7293713.4 | CF19: 768857.55 | CH19: 22220.17 | CI19: 18684.46 | CN19: 53004501 | CO19: 43842304 | CP19: 35154994 | CQ19: 51633310 | CR19: 1.296525e+08 | CS19: 1.8590506e+08 | CT19: 2.9302806e+08 | CU19: 2.3134265e+08 | CV19: 5.5742904e+08 | CW19: 64950.808 | CX19: 610016.83 | CY19: 1632.0007 | CZ19: 10401556 | DA19: 2530964.7 | DB19: 4057490.3 | DC19: 1056.6585 | DE19: 1005573.4 | DF19: 6892464.9 | DG19: 6.2099778e+08 | DH19: 3.6752757e+09 | DI19: 6.0152386e+09
A20: 16 | B20: 29273.471 | C20: 259382.25 | D20: 0.022288741 | E20: 15.709301 | F20: 260.57832 | G20: 19034.923 | H20: 5155.9401 | I20: 3903.2442 | J20: 5705.465 | K20: 2385981.2 | L20: 1891302.1 | M20: 277000.72 | N20: 13745.442 | O20: 103877.28 | P20: 332316.03 | Q20: 506162.5 | R20: 23235.808 | S20: 17710.677 | T20: 135519.23 | U20: 235545.83 | V20: 527976.71 | W20: 188980.95 | X20: 391589.97 | Y20: 19194.303 | Z20: 51525.656 | AA20: 26781.924 | AB20: 115280.67 | AC20: 43336.97 | AD20: 848679.95 | AE20: 20128.95 | AF20: 187454.05 | AG20: 264035.92 | AH20: 19972.474 | AI20: 766.05805 | AJ20: 1698.7981 | AK20: 13438.266 | AL20: 4066.1582 | AM20: 4615.4024 | AN20: 82232.381 | AO20: 5555.5304 | AP20: 65274.89 | AQ20: 1658.6842 | AR20: 675.58133 | AS20: 4693.3937 | AT20: 6795.8569 | AU20: 1025.3576 | AV20: 89.785706 | AW20: 990.08744 | AX20: 429.57118 | AY20: 2413.0646 | AZ20: 5381.2261 | BA20: 5843.2514 | BB20: 13803.273 | BC20: 46289.536 | BD20: 34463.22 | BE20: 51195.479 | BF20: 2217.933 | BG20: 7704.5523 | BH20: 2145.6667 | BI20: 6749.9628 | BJ20: 186.45004 | BK20: 86701.828 | BL20: 24573.406 | BM20: 5701.5475 | BN20: 325271.53 | BO20: 8888.6281 | BP20: 95117.868 | BQ20: 22657.511 | BR20: 65449.644 | BS20: 202840.47 | BT20: 278489.69 | BU20: 98871.016 | BV20: 282430.82 | BW20: 12699.608 | BX20: 2040.656 | BY20: 56950.219 | BZ20: 81676.043 | CA20: 901798.34 | CB20: 396746.31 | CC20: 41247.166 | CD20: 71220.569 | CF20: 232504.69 | CH20: 52185.414 | CI20: 37309.191 | CN20: 2122132.4 | CO20: 2610393.8 | CP20: 2412535.7 | CQ20: 3752167.6 | CR20: 7900913.9 | CS20: 12073580 | CT20: 18413521 | CU20: 12633831 | CV20: 26450636 | CW20: 27192.771 | CX20: 642819.14 | CY20: 8893.272 | CZ20: 610763.33 | DA20: 209568.52 | DB20: 683936.26 | DC20: 6900.5567 | DE20: 567777.71 | DF20: 195540.97 | DG20: 1.7454974e+08 | DH20: 4.8817959e+08 | DI20: 7.6675827e+08
A21: 17 | B21: 3823068.6 | C21: 965615.67 | D21: 1.803211 | E21: 15424.822 | F21: 42.885349 | G21: 73818.361 | H21: 2624112.2 | I21: 1184253.7 | J21: 70078.969 | K21: 3.5479267e+09 | L21: 3793730.2 | M21: 13092439 | N21: 8006.921 | O21: 1249194.8 | P21: 2315.7687 | Q21: 3247.0935 | R21: 1.2578026e+09 | S21: 31116006 | T21: 264933.14 | U21: 244448.19 | V21: 8931413.6 | W21: 41894755 | X21: 17503511 | Y21: 14963116 | Z21: 4740988.6 | AA21: 13991254 | AB21: 1.6566648e+08 | AC21: 16923370 | AD21: 63843274 | AE21: 3.4282102e+08 | AF21: 92828514 | AG21: 2.6110738e+08 | AH21: 7930644 | AI21: 900725.09 | AJ21: 1653370.2 | AK21: 45482610 | AL21: 11473610 | AM21: 2374587.4 | AN21: 12645525 | AO21: 7726388.6 | AP21: 8246904.2 | AQ21: 248008.34 | AR21: 53712766 | AS21: 59153.699 | AT21: 18971381 | AU21: 28500.633 | AV21: 177644.17 | AW21: 638150.25 | AX21: 594373.13 | AY21: 9271080.9 | AZ21: 1395328.4 | BA21: 7858221.1 | BB21: 13477901 | BC21: 33036249 | BD21: 85491751 | BE21: 23328753 | BF21: 1483508.4 | BG21: 768117.29 | BH21: 2078568.7 | BI21: 24474.847 | BJ21: 3423.7099 | BK21: 6.7053492e+08 | BL21: 38074136 | BM21: 103352.29 | BN21: 94327517 | BO21: 274009.67 | BP21: 59585696 | BQ21: 1130222.8 | BR21: 1668532.1 | BS21: 26493337 | BT21: 14593722 | BU21: 213549.73 | BV21: 48671420 | BW21: 551120.18 | BX21: 460.72052 | BY21: 10022695 | BZ21: 18001095 | CA21: 54986750 | CB21: 9938453.5 | CC21: 1267454.3 | CD21: 19356459 | CF21: 39926399 | CH21: 1.0393496e+08 | CI21: 73901984 | CN21: 8155873.3 | CO21: 11953324 | CP21: 10672397 | CQ21: 10657895 | CR21: 25947620 | CS21: 30718494 | CT21: 48983583 | CU21: 38916823 | CV21: 81632285 | CW21: 2285037.3 | CX21: 4617532.3 | CY21: 341501.1 | CZ21: 1.1920723e+08 | DA21: 1.7563311e+08 | DB21: 6551053.4 | DC21: 66291.48 | DE21: 1.029615e+09 | DF21: 45238174 | DG21: 3.3594999e+08 | DH21: 1.3874779e+09 | DI21: 1.0922736e+10
A22: 18 | B22: 2676502.4 | C22: 308912.72 | D22: 7.8975185 | E22: 159.9333 | F22: 247.91943 | G22: 925046.44 | H22: 1470095.9 | I22: 364413.13 | J22: 393779.75 | K22: 1.7222727e+08 | L22: 1.0487808e+09 | M22: 2.1185243e+08 | N22: 4596002.7 | O22: 4646738.1 | P22: 782836.85 | Q22: 911656.78 | R22: 43100829 | S22: 1.5174288e+09 | T22: 3.5297209e+08 | U22: 9243685.8 | V22: 3.0775416e+08 | W22: 1.478152e+08 | X22: 90002955 | Y22: 24741285 | Z22: 73474861 | AA22: 66554903 | AB22: 1.5795883e+08 | AC22: 89620866 | AD22: 2.994661e+08 | AE22: 61424360 | AF22: 1.9096466e+08 | AG22: 3.6681946e+08 | AH22: 4711107.3 | AI22: 783216.38 | AJ22: 1210238.9 | AK22: 32318615 | AL22: 7944159.7 | AM22: 1586146.8 | AN22: 11041675 | AO22: 6680597.5 | AP22: 9704149.3 | AQ22: 1688039.1 | AR22: 1035556.6 | AS22: 182649.24 | AT22: 11733107 | AU22: 94772448 | AV22: 1876832.2 | AW22: 24103478 | AX22: 9039298.3 | AY22: 12137953 | AZ22: 20902180 | BA22: 6540875.2 | BB22: 985361.91 | BC22: 15566397 | BD22: 8049162.7 | BE22: 17946469 | BF22: 12944971 | BG22: 17860807 | BH22: 14599809 | BI22: 16305362 | BJ22: 90316.689 | BK22: 68116144 | BL22: 11193781 | BM22: 87956602 | BN22: 2.0081984e+08 | BO22: 20983280 | BP22: 1.8350841e+08 | BQ22: 17035988 | BR22: 16792078 | BS22: 1.4949045e+08 | BT22: 83525585 | BU22: 62074897 | BV22: 1.3817304e+08 | BW22: 3599572.8 | BX22: 148001.15 | BY22: 6462701.3 | BZ22: 1.4351446e+08 | CA22: 3.1328647e+08 | CB22: 15850342 | CC22: 9293012.8 | CD22: 54367435 | CF22: 10174138 | CH22: 49677693 | CI22: 43611823 | CN22: 66289592 | CO22: 80349182 | CP22: 70882928 | CQ22: 68219761 | CR22: 1.6321768e+08 | CS22: 1.9113388e+08 | CT22: 3.1749439e+08 | CU22: 2.0976101e+08 | CV22: 4.2652799e+08 | CW22: 44160093 | CX22: 18074130 | CY22: 1637991.3 | CZ22: 3.1151198e+08 | DA22: 1.9554673e+08 | DB22: 3.6582065e+08 | DC22: 1076253.8 | DE22: 5739498.8 | DF22: 33904627 | DG22: 5.4421134e+08 | DH22: 2.8239516e+09 | DI22: 1.3242788e+10
A23: 19 | B23: 302363.87 | C23: 981673.86 | D23: 181.22592 | E23: 477.85749 | F23: 3147.6422 | G23: 3456938.4 | H23: 119041.3 | I23: 78058.152 | J23: 8235397.5 | K23: 22590689 | L23: 17717960 | M23: 3310286.6 | N23: 126030.22 | O23: 187137.76 | P23: 716487.94 | Q23: 23769.418 | R23: 1540759.6 | S23: 9130968.9 | T23: 77186293 | U23: 1705764.3 | V23: 23441627 | W23: 2463754.1 | X23: 1412084.6 | Y23: 624080.75 | Z23: 5757240.4 | AA23: 8222366.4 | AB23: 10660930 | AC23: 1601237.7 | AD23: 8445290.7 | AE23: 1372312.6 | AF23: 4172200.5 | AG23: 7.7385312e+08 | AH23: 28541064 | AI23: 7400585.7 | AJ23: 5305023.6 | AK23: 39909225 | AL23: 19462502 | AM23: 10374307 | AN23: 27566236 | AO23: 44193418 | AP23: 27326683 | AQ23: 1553823.3 | AR23: 742321.33 | AS23: 465203.07 | AT23: 17205588 | AU23: 15691602 | AV23: 548918.85 | AW23: 4850733.3 | AX23: 596755.06 | AY23: 1820313.8 | AZ23: 80048923 | BA23: 63805783 | BB23: 32051059 | BC23: 22844028 | BD23: 42787925 | BE23: 7.8468988e+08 | BF23: 29072119 | BG23: 1.1145451e+08 | BH23: 27391249 | BI23: 1.290993e+08 | BJ23: 1485772.4 | BK23: 43476579 | BL23: 9181541.7 | BM23: 63504738 | BN23: 6.2017998e+08 | BO23: 83479958 | BP23: 1.7878237e+08 | BQ23: 2641948.2 | BR23: 81225538 | BS23: 1.2815462e+08 | BT23: 1.3576384e+08 | BU23: 11245813 | BV23: 3.0130491e+08 | BW23: 38053965 | BX23: 30668456 | BY23: 21681652 | BZ23: 53125613 | CA23: 89587749 | CB23: 13775996 | CC23: 50263452 | CD23: 1.2338067e+08 | CF23: 83255450 | CH23: 876813.87 | CI23: 503044.99 | CN23: 8717983.1 | CO23: 11661155 | CP23: 11848444 | CQ23: 10148731 | CR23: 22167003 | CS23: 33989208 | CT23: 64072932 | CU23: 55913491 | CV23: 1.3589426e+08 | CW23: 36647694 | CX23: 84606235 | CY23: 67037770 | CZ23: 2.6729755e+08 | DA23: 3.1376785e+08 | DB23: 1.9774976e+08 | DC23: 43761090 | DE23: 1.1405456e+08 | DF23: 30642346 | DG23: 5.3556022e+08 | DH23: 1.571582e+09 | DI23: 8.3489595e+09
A24: 20 | B24: 3.0846134e+08 | C24: 2.8877931e+08 | D24: 189873.67 | E24: 279995.84 | F24: 238617.17 | G24: 1.645282e+08 | H24: 74220074 | I24: 32743404 | J24: 2.8270143e+08 | K24: 6.7346169e+09 | L24: 2.6993282e+08 | M24: 63376194 | N24: 8570149.1 | O24: 10261076 | P24: 106336.32 | Q24: 704506.03 | R24: 78682224 | S24: 92709705 | T24: 56723251 | U24: 1.8673741e+09 | V24: 1.1229223e+09 | W24: 1.5056593e+08 | X24: 80036389 | Y24: 56071055 | Z24: 1.3439792e+08 | AA24: 73045656 | AB24: 1.9332827e+08 | AC24: 1.1345703e+08 | AD24: 77654583 | AE24: 31019490 | AF24: 1.5552298e+08 | AG24: 6.1161937e+08 | AH24: 60408614 | AI24: 2163148.1 | AJ24: 20649992 | AK24: 44359475 | AL24: 6591531.7 | AM24: 14706163 | AN24: 12812688 | AO24: 19904682 | AP24: 20728221 | AQ24: 2.9740472e+09 | AR24: 2.7706232e+08 | AS24: 3.6137588e+08 | AT24: 2.6529231e+09 | AU24: 5.7279619e+08 | AV24: 10771299 | AW24: 58402538 | AX24: 2.2201227e+08 | AY24: 4.8884903e+08 | AZ24: 16639478 | BA24: 19636762 | BB24: 6405300.9 | BC24: 48684597 | BD24: 96446465 | BE24: 38272435 | BF24: 2.1923009e+08 | BG24: 5.1454767e+08 | BH24: 2.1687915e+08 | BI24: 2948306.7 | BJ24: 94513903 | BK24: 1.0443712e+09 | BL24: 2.3839631e+08 | BM24: 54585644 | BN24: 5.1527194e+08 | BO24: 97398292 | BP24: 6.9532684e+08 | BQ24: 2.2708492e+08 | BR24: 2.2354137e+08 | BS24: 1.8060297e+08 | BT24: 2.1036144e+08 | BU24: 92796131 | BV24: 1.1398944e+08 | BW24: 34302253 | BX24: 6437592.2 | BY24: 1.2103057e+08 | BZ24: 1.1217816e+08 | CA24: 5.857976e+08 | CB24: 1.7230679e+08 | CC24: 89416850 | CD24: 1.7828343e+08 | CF24: 2.8516022e+09 | CH24: 2.3176887e+08 | CI24: 1.4318875e+08 | CN24: 7.5383665e+08 | CO24: 9.4674777e+08 | CP24: 8.5669227e+08 | CQ24: 9.5680084e+08 | CR24: 2.4550798e+09 | CS24: 3.0836133e+09 | CT24: 4.9851846e+09 | CU24: 3.4637479e+09 | CV24: 6.6524142e+09 | CW24: 69051358 | CX24: 2.7696682e+09 | CY24: 71.339888 | CZ24: 1.1943099e+10 | DA24: 3.8467979e+09 | DB24: 1.0002604e+09 | DC24: 112.29355 | DE24: 16976459 | DF24: 5.7976053e+08 | DG24: 1.1811451e+10 | DH24: 9.9140073e+09 | DI24: 9.6554839e+10
A25: 21 | B25: 2.3461621e+08 | C25: 1.1774973e+08 | D25: 552.43257 | E25: 6910.0921 | F25: 1584091.6 | G25: 1.0613361e+08 | H25: 21060634 | I25: 11516555 | J25: 40720486 | K25: 5.7700191e+08 | L25: 2.6625873e+08 | M25: 43241784 | N25: 72731798 | O25: 1.4095667e+08 | P25: 1806796.2 | Q25: 4092834.8 | R25: 51063067 | S25: 1.2830579e+08 | T25: 1.6044491e+08 | U25: 1.7586322e+09 | V25: 3.9810117e+09 | W25: 1.4299687e+09 | X25: 1.2048661e+08 | Y25: 38631536 | Z25: 2.6969123e+08 | AA25: 50631038 | AB25: 5.3292978e+08 | AC25: 1.103818e+08 | AD25: 4.0712596e+08 | AE25: 55718953 | AF25: 3.2834495e+08 | AG25: 89486695 | AH25: 2497657 | AI25: 494940.48 | AJ25: 569481.58 | AK25: 2166193.8 | AL25: 1728548.1 | AM25: 726534.41 | AN25: 766079.61 | AO25: 4799045.7 | AP25: 951239.95 | AQ25: 8986106.7 | AR25: 4531505.8 | AS25: 1315036.9 | AT25: 15536253 | AU25: 3702091.6 | AV25: 135627.82 | AW25: 995077.78 | AX25: 1063402.8 | AY25: 10872444 | AZ25: 8758727.9 | BA25: 12960448 | BB25: 2774831.8 | BC25: 15176815 | BD25: 11347023 | BE25: 76223215 | BF25: 1196098.2 | BG25: 3672079 | BH25: 1618397.9 | BI25: 699035.1 | BJ25: 283079.44 | BK25: 5.6262026e+08 | BL25: 5898467.1 | BM25: 951057.47 | BN25: 4.9325911e+08 | BO25: 20753739 | BP25: 3.3520614e+08 | BQ25: 98091634 | BR25: 33467932 | BS25: 1.056032e+09 | BT25: 1.3243101e+09 | BU25: 40589598 | BV25: 36476123 | BW25: 685094.38 | BX25: 4457568.3 | BY25: 31962246 | BZ25: 4786642.9 | CA25: 77184346 | CB25: 72174184 | CC25: 1.2115997e+08 | CD25: 12916288 | CF25: 1.6483612e+08 | CH25: 4.1366552e+08 | CI25: 2.8930729e+08 | CN25: 3.0284576e+08 | CO25: 5.6459165e+08 | CP25: 4.2527424e+08 | CQ25: 5.1465853e+08 | CR25: 1.3993808e+09 | CS25: 1.2681331e+09 | CT25: 1.9702332e+09 | CU25: 1.4001517e+09 | CV25: 2.7381648e+09 | CW25: 40399249 | CX25: 4.2008854e+08 | CY25: 70947.052 | CZ25: 8.0107143e+08 | DA25: 1.8013478e+08 | DB25: 1.8896055e+09 | DC25: 175612.38 | DE25: 3.0291119e+08 | DF25: 2.0417051e+08 | DG25: 1.5155703e+10 | DH25: 5.3995503e+10 | DI25: 1.0012294e+11
A26: 22 | B26: 33384033 | C26: 18205542 | D26: 28.174331 | E26: 28818.206 | F26: 28199.2 | G26: 1099334.6 | H26: 8319400.3 | I26: 4093725.6 | J26: 375029.14 | K26: 1.6253301e+09 | L26: 9.4881754e+08 | M26: 3.1228816e+08 | N26: 6759587.4 | O26: 4920398.6 | P26: 928602.59 | Q26: 3654402 | R26: 45951518 | S26: 58468182 | T26: 85741109 | U26: 17848774 | V26: 4.4991159e+08 | W26: 5.415523e+08 | X26: 44408966 | Y26: 8483830.6 | Z26: 1.0066145e+08 | AA26: 2.1383798e+08 | AB26: 8.1526248e+08 | AC26: 1.0629846e+08 | AD26: 9.7070889e+08 | AE26: 1.3360645e+08 | AF26: 3.0984932e+08 | AG26: 8.8517845e+08 | AH26: 23079896 | AI26: 2045418.3 | AJ26: 5842558.5 | AK26: 49906022 | AL26: 13287229 | AM26: 14249485 | AN26: 16242493 | AO26: 17932879 | AP26: 11864997 | AQ26: 13387453 | AR26: 139113.54 | AS26: 125475.94 | AT26: 41232378 | AU26: 7404434.1 | AV26: 3139676.4 | AW26: 2838685.7 | AX26: 27079854 | AY26: 11981142 | AZ26: 8422823.3 | BA26: 7686078.3 | BB26: 1.5742277e+08 | BC26: 1.0357483e+08 | BD26: 13397900 | BE26: 27308108 | BF26: 754387.63 | BG26: 6784124 | BH26: 1140858.8 | BI26: 12449107 | BJ26: 29734.904 | BK26: 21958644 | BL26: 65503103 | BM26: 72852136 | BN26: 4.8297882e+08 | BO26: 4231036.6 | BP26: 92571098 | BQ26: 21870574 | BR26: 29704443 | BS26: 3.5702447e+08 | BT26: 1.0261351e+08 | BU26: 58803312 | BV26: 85184778 | BW26: 2266677.1 | BX26: 330464.01 | BY26: 11114972 | BZ26: 6714501.4 | CA26: 4.3758659e+08 | CB26: 2.0780002e+08 | CC26: 36082387 | CD26: 27746121 | CF26: 4.0300744e+08 | CH26: 10166531 | CI26: 7049585.4 | CN26: 64308210 | CO26: 88582384 | CP26: 80512795 | CQ26: 84417054 | CR26: 2.011862e+08 | CS26: 2.4664059e+08 | CT26: 3.3386926e+08 | CU26: 2.3934524e+08 | CV26: 5.1472335e+08 | CW26: 10900186 | CX26: 1.1803076e+08 | CY26: 887368.4 | CZ26: 1.8164895e+08 | DA26: 75443257 | DB26: 4.1752569e+08 | DC26: 486660.63 | DE26: 96893879 | DF26: 49930309 | DG26: 1.4186967e+09 | DH26: 6.1716995e+09 | DI26: 2.1297642e+10
A27: 23 | B27: 5965279.5 | C27: 167583.28 | D27: 10.397707 | E27: 10259.349 | F27: 104.67876 | G27: 20966302 | H27: 9984536.5 | I27: 8232402.8 | J27: 7972665.4 | K27: 7.1175819e+09 | L27: 85796108 | M27: 4.5441313e+08 | N27: 144577.62 | O27: 13940.309 | P27: 2070.6919 | Q27: 2475.0135 | R27: 42528362 | S27: 5915287.6 | T27: 115268 | U27: 67043112 | V27: 95396080 | W27: 64360883 | X27: 1.1562626e+09 | Y27: 49191041 | Z27: 65771379 | AA27: 59896559 | AB27: 1.7704219e+08 | AC27: 96775500 | AD27: 4.5953493e+08 | AE27: 15972661 | AF27: 65006349 | AG27: 6613304.1 | AH27: 9175531.8 | AI27: 774862.68 | AJ27: 527768.7 | AK27: 3148687.2 | AL27: 136610.03 | AM27: 117942.75 | AN27: 4701248.5 | AO27: 6760386.1 | AP27: 198849.82 | AQ27: 170726.95 | AR27: 631254.37 | AS27: 45350.074 | AT27: 12225737 | AU27: 61309.283 | AV27: 33628.822 | AW27: 169659.87 | AX27: 370739.78 | AY27: 2742327.6 | AZ27: 235918.03 | BA27: 225599.94 | BB27: 37983073 | BC27: 1.3352178e+08 | BD27: 94513715 | BE27: 1867346.4 | BF27: 684442.45 | BG27: 2416364.9 | BH27: 842615.48 | BI27: 1042037.6 | BJ27: 5546.0451 | BK27: 36201701 | BL27: 59773720 | BM27: 8695474.4 | BN27: 4.1001311e+08 | BO27: 2897787.1 | BP27: 81968477 | BQ27: 19560020 | BR27: 7850287.3 | BS27: 1.135663e+08 | BT27: 94875000 | BU27: 8236923.8 | BV27: 37238381 | BW27: 1924482.9 | BX27: 1694.2873 | BY27: 11727386 | BZ27: 5538392.9 | CA27: 1.8267031e+08 | CB27: 42830729 | CC27: 24493749 | CD27: 23681712 | CF27: 5.9289344e+08 | CH27: 178539.57 | CI27: 99576.575 | CN27: 49908069 | CO27: 45376138 | CP27: 44605783 | CQ27: 64575971 | CR27: 1.1007308e+08 | CS27: 1.584657e+08 | CT27: 1.7358875e+08 | CU27: 1.3524916e+08 | CV27: 2.9361354e+08 | CW27: 14879400 | CX27: 19209522 | CY27: 6220.3166 | CZ27: 55849027 | DA27: 16051673 | DB27: 61264878 | DC27: 10080.402 | DE27: 3506146.1 | DF27: 56372441 | DG27: 5.5389277e+08 | DH27: 1.1980064e+09 | DI27: 1.5275432e+10
A28: 24 | B28: 628288.81 | C28: 847865.54 | D28: 137.01827 | E28: 349.20679 | F28: 245.87464 | G28: 30743900 | H28: 5459151.9 | I28: 1499534.2 | J28: 450023.44 | K28: 1.5009915e+08 | L28: 11682918 | M28: 36193983 | N28: 21871.887 | O28: 1241431 | P28: 6671.5543 | Q28: 3214.0758 | R28: 6242128.8 | S28: 11871354 | T28: 238328.26 | U28: 1769179.2 | V28: 2377080.5 | W28: 20073273 | X28: 27799580 | Y28: 6.5051849e+08 | Z28: 1.8200516e+09 | AA28: 5.0852996e+08 | AB28: 6.5444436e+08 | AC28: 5.1844816e+08 | AD28: 6.7532897e+08 | AE28: 66237014 | AF28: 1.6259295e+08 | AG28: 13611989 | AH28: 82394.059 | AI28: 12808.99 | AJ28: 17484.008 | AK28: 64183.81 | AL28: 16103.499 | AM28: 18622.705 | AN28: 166179.17 | AO28: 120218.77 | AP28: 50609.573 | AQ28: 2534530.8 | AR28: 7904527.8 | AS28: 491253.66 | AT28: 2133107.7 | AU28: 497956.14 | AV28: 279325.57 | AW28: 1928594.1 | AX28: 168114.4 | AY28: 424849.57 | AZ28: 246609.31 | BA28: 413891.53 | BB28: 2693954.8 | BC28: 6123037.4 | BD28: 4482202.8 | BE28: 19999362 | BF28: 187837.41 | BG28: 1148644.8 | BH28: 201868.34 | BI28: 27674.266 | BJ28: 74464.815 | BK28: 97591360 | BL28: 3033330.8 | BM28: 104076.31 | BN28: 38686828 | BO28: 1064305.3 | BP28: 18556326 | BQ28: 10159866 | BR28: 6973237.9 | BS28: 9225809.7 | BT28: 625882.44 | BU28: 429205.41 | BV28: 8179534 | BW28: 1297672.4 | BX28: 5138.3823 | BY28: 9181623 | BZ28: 939173.95 | CA28: 4483619.6 | CB28: 25927123 | CC28: 3167821.3 | CD28: 1940993.9 | CF28: 32267338 | CH28: 382580.21 | CI28: 279955.59 | CN28: 1742710.4 | CO28: 2451727.9 | CP28: 2030621.3 | CQ28: 2356581.3 | CR28: 5535326.7 | CS28: 6262175.6 | CT28: 9249606.7 | CU28: 6881665 | CV28: 14867800 | CW28: 4284905.4 | CX28: 9977167.7 | CY28: 39535.735 | CZ28: 11048348 | DA28: 2970629.2 | DB28: 1560249.1 | DC28: 50396.963 | DE28: 11553231 | DF28: 20424559 | DG28: 1.7843726e+09 | DH28: 4.4923503e+09 | DI28: 1.2096036e+10
A29: 25 | B29: 7106896 | C29: 55443938 | D29: 154.88202 | E29: 50744.639 | F29: 10113.786 | G29: 1.0823118e+08 | H29: 8820423.1 | I29: 7054428.8 | J29: 90120410 | K29: 6.4011918e+09 | L29: 6.9938398e+08 | M29: 5.0502516e+08 | N29: 7101059.8 | O29: 8910693.7 | P29: 1999621.5 | Q29: 1318422.5 | R29: 1.2509751e+08 | S29: 1.4896265e+08 | T29: 35161345 | U29: 70586894 | V29: 3.5962226e+08 | W29: 2.46174e+08 | X29: 95043771 | Y29: 1.286813e+08 | Z29: 1.8664742e+09 | AA29: 9.0555204e+08 | AB29: 2.3979766e+09 | AC29: 6.3639205e+08 | AD29: 1.6212233e+09 | AE29: 1.9390155e+08 | AF29: 3.791237e+08 | AG29: 1.5049691e+08 | AH29: 10486847 | AI29: 2162770.1 | AJ29: 1047647 | AK29: 6508535.8 | AL29: 2876802.3 | AM29: 2454022.8 | AN29: 4154312 | AO29: 20960320 | AP29: 3733895.6 | AQ29: 15228652 | AR29: 11156421 | AS29: 1.0204046e+08 | AT29: 1.0902404e+08 | AU29: 43579089 | AV29: 1.308328e+08 | AW29: 4483859.5 | AX29: 3073985.6 | AY29: 34604650 | AZ29: 45782066 | BA29: 3217723.9 | BB29: 2.0404548e+08 | BC29: 2.5557032e+08 | BD29: 99747097 | BE29: 61474028 | BF29: 5108490.9 | BG29: 15825429 | BH29: 4477729 | BI29: 769674.52 | BJ29: 1431853.5 | BK29: 1.4489828e+08 | BL29: 1.0924906e+08 | BM29: 1073314.9 | BN29: 5.6716514e+08 | BO29: 29449530 | BP29: 1.4556803e+08 | BQ29: 1.981866e+08 | BR29: 39447310 | BS29: 28073418 | BT29: 51841820 | BU29: 1689309.3 | BV29: 1.4185938e+08 | BW29: 3901895.7 | BX29: 188175.46 | BY29: 26538002 | BZ29: 64660168 | CA29: 2.1271965e+08 | CB29: 3.6886825e+08 | CC29: 15661770 | CD29: 54810998 | CF29: 8.3515988e+08 | CH29: 10588176 | CI29: 6278585.5 | CN29: 33302624 | CO29: 47769855 | CP29: 39651578 | CQ29: 43512170 | CR29: 1.3479171e+08 | CS29: 1.605069e+08 | CT29: 2.3720648e+08 | CU29: 1.9452894e+08 | CV29: 5.019572e+08 | CW29: 19238306 | CX29: 7.3885939e+08 | CY29: 17926440 | CZ29: 4.4174436e+08 | DA29: 23637576 | DB29: 73415283 | DC29: 9361727.7 | DE29: 2.5922969e+09 | DF29: 1.6218738e+08 | DG29: 2.8688178e+09 | DH29: 1.3064191e+10 | DI29: 4.2930878e+10
A30: 26 | B30: 2629149.6 | C30: 4750820.7 | D30: 2.624585 | E30: 5240.0915 | F30: 1637.0259 | G30: 23086747 | H30: 4099818.6 | I30: 5998589.7 | J30: 3205196.7 | K30: 5.7380439e+08 | L30: 25946048 | M30: 50727021 | N30: 66988.822 | O30: 88541.973 | P30: 39745.026 | Q30: 6138.9652 | R30: 4566383.5 | S30: 1505310.5 | T30: 7867953.6 | U30: 733084.03 | V30: 22507691 | W30: 11325865 | X30: 1462210.7 | Y30: 4302501.5 | Z30: 42764644 | AA30: 2.4028787e+08 | AB30: 33257131 | AC30: 33762671 | AD30: 5.1109157e+08 | AE30: 974492.39 | AF30: 11014524 | AG30: 19308392 | AH30: 1764201.6 | AI30: 45964.71 | AJ30: 263637.69 | AK30: 1040342.3 | AL30: 207735.28 | AM30: 440721.95 | AN30: 1111583.7 | AO30: 429518.44 | AP30: 991020.33 | AQ30: 180275.55 | AR30: 446176.52 | AS30: 734993.32 | AT30: 10362908 | AU30: 2758176.2 | AV30: 1405310 | AW30: 5145282.1 | AX30: 82717.414 | AY30: 11228314 | AZ30: 1016254.4 | BA30: 1490127.7 | BB30: 14084495 | BC30: 4934759.9 | BD30: 4553896.1 | BE30: 21372114 | BF30: 30850.213 | BG30: 1116356.7 | BH30: 80300.75 | BI30: 1647389.1 | BJ30: 8049.255 | BK30: 3024532.7 | BL30: 9254362.6 | BM30: 37200.971 | BN30: 56070227 | BO30: 1435237.8 | BP30: 31255492 | BQ30: 45545225 | BR30: 31987205 | BS30: 7480928.9 | BT30: 7044211.2 | BU30: 2104402.2 | BV30: 3692376.6 | BW30: 175980.85 | BX30: 34025.332 | BY30: 2197451.3 | BZ30: 687136.17 | CA30: 9238464.8 | CB30: 1.0469677e+08 | CC30: 3920382.3 | CD30: 4483643.3 | CF30: 42504164 | CH30: 2172236.3 | CI30: 1928394.2 | CN30: 3355124.1 | CO30: 4309871.4 | CP30: 3086748.1 | CQ30: 3879802 | CR30: 8972021.6 | CS30: 13655917 | CT30: 24905031 | CU30: 20401578 | CV30: 44535764 | CW30: 885718.63 | CX30: 27908812 | CY30: 4183721.2 | CZ30: 72323079 | DA30: 15577668 | DB30: 18065624 | DC30: 50344432 | DE30: 9.0667891e+09 | DF30: 82155078 | DG30: 1.0241635e+10 | DH30: 1.5622226e+10 | DI30: 3.7430328e+10
A31: 27 | B31: 1218730.1 | C31: 777826.18 | D31: 8.411211 | E31: 493.41435 | F31: 1525.1082 | G31: 811622.5 | H31: 123754.16 | I31: 381054.31 | J31: 1150049.8 | K31: 1.6716742e+08 | L31: 10686020 | M31: 1.6938315e+08 | N31: 4015465.7 | O31: 5466054.6 | P31: 779423.44 | Q31: 1258986.9 | R31: 39851789 | S31: 25479169 | T31: 21030384 | U31: 11340608 | V31: 96647588 | W31: 54148544 | X31: 26795945 | Y31: 25658492 | Z31: 2.1013461e+08 | AA31: 2.1604648e+08 | AB31: 7.7750696e+09 | AC31: 2.3897356e+08 | AD31: 6.6473344e+08 | AE31: 37944868 | AF31: 1.3476738e+08 | AG31: 1.55195e+09 | AH31: 8126127.7 | AI31: 102392.48 | AJ31: 466966.52 | AK31: 2223163.3 | AL31: 4841476.1 | AM31: 962002.28 | AN31: 706094.05 | AO31: 914503.98 | AP31: 1599503.1 | AQ31: 162825.64 | AR31: 696961.88 | AS31: 119916.08 | AT31: 2181523 | AU31: 325603.7 | AV31: 120084.25 | AW31: 353565.08 | AX31: 54206.004 | AY31: 1901649.5 | AZ31: 62831070 | BA31: 1.4389918e+08 | BB31: 5155819.3 | BC31: 1.7907206e+08 | BD31: 1.1703534e+08 | BE31: 33905095 | BF31: 2572429.1 | BG31: 11008380 | BH31: 3446475 | BI31: 723217.79 | BJ31: 6813683.7 | BK31: 6911871.9 | BL31: 2556288.6 | BM31: 1092023 | BN31: 4.331598e+08 | BO31: 26724579 | BP31: 79940667 | BQ31: 8943365 | BR31: 31499147 | BS31: 58785903 | BT31: 9824065.5 | BU31: 2583757.9 | BV31: 7216814.8 | BW31: 689220.65 | BX31: 50352.336 | BY31: 1349770.7 | BZ31: 23261191 | CA31: 4501884.1 | CB31: 2.8778391e+08 | CC31: 3247890.5 | CD31: 9143245.9 | CF31: 46476494 | CH31: 610998.14 | CI31: 473193 | CN31: 34507078 | CO31: 44952392 | CP31: 40776472 | CQ31: 53772970 | CR31: 1.270939e+08 | CS31: 1.5501381e+08 | CT31: 2.6926903e+08 | CU31: 2.3347211e+08 | CV31: 4.6029724e+08 | CW31: 13724226 | CX31: 4.5359502e+08 | CY31: 57199337 | CZ31: 31066700 | DA31: 11484455 | DB31: 8027673.9 | DC31: 78933560 | DE31: 1.0025332e+10 | DF31: 3.1960421e+08 | DG31: 2.9539432e+10 | DH31: 1.3842767e+11 | DI31: 1.9351816e+11
... A36: 32 | B36: 7.0544783e+08 | C36: 2.0006475e+09 | D36: 7946154.2 | E36: 352739.56 | F36: 3140540.1 | G36: 4.0994645e+08 | H36: 1.3142775e+08 | I36: 88275106 | J36: 7.2588942e+08 | K36: 1.8100444e+10 | L36: 1.1483746e+10 | M36: 3.5302937e+09 | N36: 1.1106843e+08 | O36: 96754436 | P36: 3.2704619e+08 | Q36: 74956734 | R36: 1.2826984e+09 | S36: 1.2052529e+09 | T36: 5.1977732e+08 | U36: 4.1536029e+09 | V36: 8.2253925e+09 | W36: 1.6552387e+09 | X36: 9.3985082e+08 | Y36: 1.3007759e+09 | Z36: 2.8800674e+09 | AA36: 3.2089997e+09 | AB36: 1.6747354e+10 | AC36: 2.3378235e+09 | AD36: 1.6559966e+10 | AE36: 7.1134036e+08 | AF36: 3.0987266e+09 | AG36: 9.9278886e+09 | AH36: 4.7534622e+08 | AI36: 46704365 | AJ36: 80857803 | AK36: 3.6155663e+08 | AL36: 1.1054418e+08 | AM36: 80321567 | AN36: 2.435464e+08 | AO36: 3.4161932e+08 | AP36: 2.8963495e+08 | AQ36: 4.5697413e+08 | AR36: 1.6213369e+08 | AS36: 1.7423417e+08 | AT36: 1.7548946e+09 | AU36: 4.0780633e+08 | AV36: 64764849 | AW36: 1.1419236e+08 | AX36: 1.4749181e+08 | AY36: 4.3134714e+08 | AZ36: 2.3850834e+09 | BA36: 84594200 | BB36: 5.3670042e+08 | BC36: 1.2051282e+09 | BD36: 6.6502893e+08 | BE36: 7.0188897e+08 | BF36: 1.261968e+08 | BG36: 3.7728145e+08 | BH36: 1.3268143e+08 | BI36: 88992628 | BJ36: 1.1871163e+08 | BK36: 1.7150922e+09 | BL36: 2.7021798e+09 | BM36: 1.9343976e+08 | BN36: 5.0507609e+09 | BO36: 5.9493445e+08 | BP36: 2.1329624e+09 | BQ36: 6.5642555e+08 | BR36: 6.2645839e+08 | BS36: 5.8311329e+09 | BT36: 2.8147786e+09 | BU36: 5.3824609e+08 | BV36: 1.3464983e+09 | BW36: 1.0803558e+08 | BX36: 40183912 | BY36: 6.0545986e+08 | BZ36: 4.7211627e+08 | CA36: 5.2223381e+09 | CB36: 2.6580194e+09 | CC36: 5.4198605e+08 | CD36: 5.4811546e+08 | CF36: 2.6198247e+09 | CH36: 9.0234492e+08 | CI36: 6.6503973e+08 | CN36: 3.3730604e+09 | CO36: 4.230406e+09 | CP36: 3.515707e+09 | CQ36: 4.0710336e+09 | CR36: 1.0021867e+10 | CS36: 1.2302338e+10 | CT36: 2.034404e+10 | CU36: 1.5580128e+10 | CV36: 3.2866439e+10 | CW36: 2.5643789e+08 | CX36: 6.0218278e+09 | CY36: 5.2554642e+08 | CZ36: 4.9951238e+09 | DA36: 1.7784811e+09 | DB36: 4.0917411e+09 | DC36: 1.3645516e+09 | DE36: 5.0824167e+08 | DF36: 1.5248673e+09 | DG36: 2.8425292e+10 | DH36: 3.1510186e+10 | DI36: 3.5061208e+11
A37: 33 | B37: 10102.257 | C37: 589901.71 | E37: 1590.3622 | G37: 4236172.4 | H37: 5222249.2 | I37: 1767443.9 | J37: 657656.12 | K37: 2.4322123e+08 | L37: 72772922 | M37: 86447727 | N37: 50847.36 | O37: 346220.09 | R37: 24758792 | S37: 22239321 | T37: 4488158.2 | U37: 1950387.6 | V37: 44360018 | W37: 7818882.1 | X37: 15855646 | Y37: 4691406.9 | Z37: 34841279 | AA37: 78951234 | AB37: 69693164 | AC37: 754062.55 | AD37: 1.3688882e+08 | AE37: 10328258 | AF37: 43159364 | AG37: 4018296.3 | AH37: 30735604 | AI37: 1435588.6 | AJ37: 13404480 | AK37: 51713697 | AL37: 18688428 | AM37: 3658749.7 | AN37: 3342834.8 | AO37: 10395068 | AP37: 12358705 | AR37: 331090.6 | AS37: 2712245 | AT37: 1.7715262e+08 | AU37: 1303392.6 | AV37: 8047.6802 | AW37: 441825.82 | AX37: 314707.69 | AY37: 5757381.5 | AZ37: 3829996.1 | BA37: 5254704.6 | BB37: 322044.26 | BC37: 5824391.2 | BD37: 2112511.5 | BE37: 391022.99 | BF37: 904437.36 | BG37: 1003147.2 | BH37: 1605695.7 | BI37: 586769.81 | BK37: 80968560 | BL37: 59828766 | BN37: 85558768 | BP37: 2.8152047e+08 | BQ37: 9855773.7 | BR37: 315550.72 | BS37: 291510.41 | BT37: 115325.84 | BU37: 10245.345 | BV37: 190498.5 | BW37: 923078.7 | BX37: 14317.277 | BY37: 1966036.5 | BZ37: 5648240.4 | CA37: 20030371 | CB37: 8.7476927e+08 | CC37: 26217868 | CD37: 51486498 | CF37: 563412.66 | CH37: 1661.9155 | CI37: 1551.8415 | CN37: 1.2834572e+09 | CO37: 1.5663951e+09 | CP37: 1.3334917e+09 | CQ37: 1.528504e+09 | CR37: 3.7890404e+09 | CS37: 4.9666865e+09 | CT37: 8.1813599e+09 | CU37: 6.7449264e+09 | CV37: 1.4337429e+10 | CW37: 55170.867 | CZ37: 301427.45 | DA37: 891595.95 | DB37: 51744.416 | DE37: 19718512 | DH37: 246718.5 | DI37: 4.6528544e+10
A38: 34 | B38: 1722.9289 | C38: 5974.6602 | G38: 64046.125 | H38: 4406.9346 | I38: 1368.4782 | J38: 143571.82 | K38: 1.8936791e+08 | L38: 3449618.9 | M38: 3179532.7 | O38: 360192.95 | R38: 6774052.8 | S38: 472638.86 | T38: 25540164 | U38: 3186305.3 | V38: 15942940 | W38: 493063.99 | X38: 9474.8188 | Y38: 19552.267 | Z38: 1009760.5 | AA38: 2806672.9 | AB38: 4461580.6 | AC38: 2200743.6 | AD38: 1311243.6 | AE38: 1852250 | AF38: 6374280.7 | AG38: 15758694 | AH38: 3784727.6 | AI38: 255835.84 | AJ38: 338728.85 | AK38: 1733633.3 | AL38: 572906 | AM38: 633853.91 | AN38: 563718.17 | AO38: 2163089.8 | AP38: 4914188.5 | AR38: 24207.891 | AS38: 4772160.2 | AT38: 2181390.6 | AU38: 4893.7129 | AV38: 225367.31 | AW38: 44662.866 | AX38: 390507.5 | AY38: 6211.3142 | AZ38: 417814.95 | BA38: 478889.86 | BC38: 80615.262 | BD38: 1171328.5 | BE38: 7927719.6 | BF38: 1523394.4 | BG38: 6642329.2 | BH38: 2501546.5 | BI38: 526103.97 | BK38: 59225656 | BL38: 915802.83 | BN38: 13181231 | BP38: 15345875 | BQ38: 427037.03 | BR38: 3876225.9 | BS38: 10933826 | BT38: 2844350.9 | BU38: 2378815.6 | BV38: 4618475.3 | BW38: 4617.538 | BX38: 270107.76 | BY38: 473888.85 | BZ38: 36779579 | CA38: 1.0601255e+08 | CB38: 34726638 | CC38: 2272125.9 | CD38: 3826599.7 | CH38: 2924.1189 | CI38: 2730.4451 | CN38: 4.5188599e+08 | CO38: 5.5153459e+08 | CP38: 4.695353e+08 | CQ38: 5.3899468e+08 | CR38: 1.3361276e+09 | CS38: 1.7506019e+09 | CT38: 2.8852839e+09 | CU38: 2.3784797e+09 | CV38: 5.054899e+09 | CW38: 589038.42 | CX38: 106581.88 | CZ38: 1163862.2 | DA38: 6160871.5 | DB38: 449919.53 | DE38: 8645329.2 | DH38: 1.1287916e+09 | DI38: 1.719004e+10
